{
 "cells": [
  {
   "cell_type": "code",
   "execution_count": 2,
   "id": "4fc4370e",
   "metadata": {},
   "outputs": [
    {
     "name": "stdout",
     "output_type": "stream",
     "text": [
      "Requirement already satisfied: tensorflow in /home/mohammad/anaconda3/lib/python3.9/site-packages (2.12.0)\n",
      "Requirement already satisfied: absl-py>=1.0.0 in /home/mohammad/anaconda3/lib/python3.9/site-packages (from tensorflow) (1.4.0)\n",
      "Requirement already satisfied: astunparse>=1.6.0 in /home/mohammad/anaconda3/lib/python3.9/site-packages (from tensorflow) (1.6.3)\n",
      "Requirement already satisfied: flatbuffers>=2.0 in /home/mohammad/anaconda3/lib/python3.9/site-packages (from tensorflow) (23.5.9)\n",
      "Requirement already satisfied: gast<=0.4.0,>=0.2.1 in /home/mohammad/anaconda3/lib/python3.9/site-packages (from tensorflow) (0.4.0)\n",
      "Requirement already satisfied: google-pasta>=0.1.1 in /home/mohammad/anaconda3/lib/python3.9/site-packages (from tensorflow) (0.2.0)\n",
      "Requirement already satisfied: grpcio<2.0,>=1.24.3 in /home/mohammad/anaconda3/lib/python3.9/site-packages (from tensorflow) (1.54.2)\n",
      "Requirement already satisfied: h5py>=2.9.0 in /home/mohammad/anaconda3/lib/python3.9/site-packages (from tensorflow) (3.7.0)\n",
      "Requirement already satisfied: jax>=0.3.15 in /home/mohammad/anaconda3/lib/python3.9/site-packages (from tensorflow) (0.4.10)\n",
      "Requirement already satisfied: keras<2.13,>=2.12.0 in /home/mohammad/anaconda3/lib/python3.9/site-packages (from tensorflow) (2.12.0)\n",
      "Requirement already satisfied: libclang>=13.0.0 in /home/mohammad/anaconda3/lib/python3.9/site-packages (from tensorflow) (16.0.0)\n",
      "Requirement already satisfied: numpy<1.24,>=1.22 in /home/mohammad/anaconda3/lib/python3.9/site-packages (from tensorflow) (1.23.5)\n",
      "Requirement already satisfied: opt-einsum>=2.3.2 in /home/mohammad/anaconda3/lib/python3.9/site-packages (from tensorflow) (3.3.0)\n",
      "Requirement already satisfied: packaging in /home/mohammad/anaconda3/lib/python3.9/site-packages (from tensorflow) (21.3)\n",
      "Requirement already satisfied: protobuf!=4.21.0,!=4.21.1,!=4.21.2,!=4.21.3,!=4.21.4,!=4.21.5,<5.0.0dev,>=3.20.3 in /home/mohammad/anaconda3/lib/python3.9/site-packages (from tensorflow) (3.20.3)\n",
      "Requirement already satisfied: setuptools in /home/mohammad/anaconda3/lib/python3.9/site-packages (from tensorflow) (63.4.1)\n",
      "Requirement already satisfied: six>=1.12.0 in /home/mohammad/anaconda3/lib/python3.9/site-packages (from tensorflow) (1.16.0)\n",
      "Requirement already satisfied: tensorboard<2.13,>=2.12 in /home/mohammad/anaconda3/lib/python3.9/site-packages (from tensorflow) (2.12.3)\n",
      "Requirement already satisfied: tensorflow-estimator<2.13,>=2.12.0 in /home/mohammad/anaconda3/lib/python3.9/site-packages (from tensorflow) (2.12.0)\n",
      "Requirement already satisfied: termcolor>=1.1.0 in /home/mohammad/anaconda3/lib/python3.9/site-packages (from tensorflow) (2.3.0)\n",
      "Requirement already satisfied: typing-extensions>=3.6.6 in /home/mohammad/anaconda3/lib/python3.9/site-packages (from tensorflow) (4.3.0)\n",
      "Requirement already satisfied: wrapt<1.15,>=1.11.0 in /home/mohammad/anaconda3/lib/python3.9/site-packages (from tensorflow) (1.14.1)\n",
      "Requirement already satisfied: tensorflow-io-gcs-filesystem>=0.23.1 in /home/mohammad/anaconda3/lib/python3.9/site-packages (from tensorflow) (0.32.0)\n",
      "Requirement already satisfied: wheel<1.0,>=0.23.0 in /home/mohammad/anaconda3/lib/python3.9/site-packages (from astunparse>=1.6.0->tensorflow) (0.37.1)\n",
      "Requirement already satisfied: ml-dtypes>=0.1.0 in /home/mohammad/anaconda3/lib/python3.9/site-packages (from jax>=0.3.15->tensorflow) (0.1.0)\n",
      "Requirement already satisfied: scipy>=1.7 in /home/mohammad/anaconda3/lib/python3.9/site-packages (from jax>=0.3.15->tensorflow) (1.9.1)\n",
      "Requirement already satisfied: google-auth<3,>=1.6.3 in /home/mohammad/anaconda3/lib/python3.9/site-packages (from tensorboard<2.13,>=2.12->tensorflow) (2.18.1)\n",
      "Requirement already satisfied: google-auth-oauthlib<1.1,>=0.5 in /home/mohammad/anaconda3/lib/python3.9/site-packages (from tensorboard<2.13,>=2.12->tensorflow) (1.0.0)\n",
      "Requirement already satisfied: markdown>=2.6.8 in /home/mohammad/anaconda3/lib/python3.9/site-packages (from tensorboard<2.13,>=2.12->tensorflow) (3.3.4)\n",
      "Requirement already satisfied: requests<3,>=2.21.0 in /home/mohammad/anaconda3/lib/python3.9/site-packages (from tensorboard<2.13,>=2.12->tensorflow) (2.28.1)\n",
      "Requirement already satisfied: tensorboard-data-server<0.8.0,>=0.7.0 in /home/mohammad/anaconda3/lib/python3.9/site-packages (from tensorboard<2.13,>=2.12->tensorflow) (0.7.0)\n",
      "Requirement already satisfied: werkzeug>=1.0.1 in /home/mohammad/anaconda3/lib/python3.9/site-packages (from tensorboard<2.13,>=2.12->tensorflow) (2.0.3)\n",
      "Requirement already satisfied: pyparsing!=3.0.5,>=2.0.2 in /home/mohammad/anaconda3/lib/python3.9/site-packages (from packaging->tensorflow) (3.0.9)\n",
      "Requirement already satisfied: cachetools<6.0,>=2.0.0 in /home/mohammad/anaconda3/lib/python3.9/site-packages (from google-auth<3,>=1.6.3->tensorboard<2.13,>=2.12->tensorflow) (5.3.0)\n",
      "Requirement already satisfied: pyasn1-modules>=0.2.1 in /home/mohammad/anaconda3/lib/python3.9/site-packages (from google-auth<3,>=1.6.3->tensorboard<2.13,>=2.12->tensorflow) (0.2.8)\n",
      "Requirement already satisfied: urllib3<2.0 in /home/mohammad/anaconda3/lib/python3.9/site-packages (from google-auth<3,>=1.6.3->tensorboard<2.13,>=2.12->tensorflow) (1.26.11)\n",
      "Requirement already satisfied: rsa<5,>=3.1.4 in /home/mohammad/anaconda3/lib/python3.9/site-packages (from google-auth<3,>=1.6.3->tensorboard<2.13,>=2.12->tensorflow) (4.9)\n",
      "Requirement already satisfied: requests-oauthlib>=0.7.0 in /home/mohammad/anaconda3/lib/python3.9/site-packages (from google-auth-oauthlib<1.1,>=0.5->tensorboard<2.13,>=2.12->tensorflow) (1.3.1)\n",
      "Requirement already satisfied: charset-normalizer<3,>=2 in /home/mohammad/anaconda3/lib/python3.9/site-packages (from requests<3,>=2.21.0->tensorboard<2.13,>=2.12->tensorflow) (2.0.4)\n",
      "Requirement already satisfied: idna<4,>=2.5 in /home/mohammad/anaconda3/lib/python3.9/site-packages (from requests<3,>=2.21.0->tensorboard<2.13,>=2.12->tensorflow) (3.3)\n",
      "Requirement already satisfied: certifi>=2017.4.17 in /home/mohammad/anaconda3/lib/python3.9/site-packages (from requests<3,>=2.21.0->tensorboard<2.13,>=2.12->tensorflow) (2022.9.14)\n",
      "Requirement already satisfied: pyasn1<0.5.0,>=0.4.6 in /home/mohammad/anaconda3/lib/python3.9/site-packages (from pyasn1-modules>=0.2.1->google-auth<3,>=1.6.3->tensorboard<2.13,>=2.12->tensorflow) (0.4.8)\n",
      "Requirement already satisfied: oauthlib>=3.0.0 in /home/mohammad/anaconda3/lib/python3.9/site-packages (from requests-oauthlib>=0.7.0->google-auth-oauthlib<1.1,>=0.5->tensorboard<2.13,>=2.12->tensorflow) (3.2.2)\n",
      "Requirement already satisfied: keras in /home/mohammad/anaconda3/lib/python3.9/site-packages (2.12.0)\n",
      "Collecting torch\n",
      "\u001b[33m  WARNING: Retrying (Retry(total=4, connect=None, read=None, redirect=None, status=None)) after connection broken by 'ProtocolError('Connection aborted.', ConnectionResetError(104, 'Connection reset by peer'))': /packages/e5/9a/ce0fe125f226ffce8deba6a18bd8d0b9f589aa236780a83a6d70b5525f56/torch-2.0.1-cp39-cp39-manylinux1_x86_64.whl\u001b[0m\u001b[33m\n",
      "\u001b[0m  Downloading torch-2.0.1-cp39-cp39-manylinux1_x86_64.whl (619.9 MB)\n",
      "\u001b[2K     \u001b[38;2;114;156;31m━━━━━━━━━━━━━━━━━━━━━━━━━━━━━━━━━━━━━\u001b[0m \u001b[32m619.9/619.9 MB\u001b[0m \u001b[31m512.6 kB/s\u001b[0m eta \u001b[36m0:00:00\u001b[0mm eta \u001b[36m0:00:01\u001b[0m[36m0:00:06\u001b[0m\n",
      "\u001b[?25hRequirement already satisfied: filelock in /home/mohammad/anaconda3/lib/python3.9/site-packages (from torch) (3.6.0)\n",
      "Requirement already satisfied: typing-extensions in /home/mohammad/anaconda3/lib/python3.9/site-packages (from torch) (4.3.0)\n",
      "Requirement already satisfied: sympy in /home/mohammad/anaconda3/lib/python3.9/site-packages (from torch) (1.10.1)\n",
      "Requirement already satisfied: networkx in /home/mohammad/anaconda3/lib/python3.9/site-packages (from torch) (2.8.4)\n",
      "Requirement already satisfied: jinja2 in /home/mohammad/anaconda3/lib/python3.9/site-packages (from torch) (2.11.3)\n",
      "\u001b[33mWARNING: Retrying (Retry(total=4, connect=None, read=None, redirect=None, status=None)) after connection broken by 'ReadTimeoutError(\"HTTPSConnectionPool(host='pypi.org', port=443): Read timed out. (read timeout=15)\")': /simple/nvidia-cuda-nvrtc-cu11/\u001b[0m\u001b[33m\n",
      "\u001b[0m\u001b[33mWARNING: Retrying (Retry(total=3, connect=None, read=None, redirect=None, status=None)) after connection broken by 'ProtocolError('Connection aborted.', ConnectionResetError(104, 'Connection reset by peer'))': /simple/nvidia-cuda-nvrtc-cu11/\u001b[0m\u001b[33m\n"
     ]
    },
    {
     "name": "stdout",
     "output_type": "stream",
     "text": [
      "\u001b[0mCollecting nvidia-cuda-nvrtc-cu11==11.7.99 (from torch)\n",
      "  Downloading nvidia_cuda_nvrtc_cu11-11.7.99-2-py3-none-manylinux1_x86_64.whl (21.0 MB)\n",
      "\u001b[2K     \u001b[38;2;114;156;31m━━━━━━━━━━━━━━━━━━━━━━━━━━━━━━━━━━━━━━━━\u001b[0m \u001b[32m21.0/21.0 MB\u001b[0m \u001b[31m3.1 MB/s\u001b[0m eta \u001b[36m0:00:00\u001b[0mm eta \u001b[36m0:00:01\u001b[0m[36m0:00:01\u001b[0m\n",
      "\u001b[?25hCollecting nvidia-cuda-runtime-cu11==11.7.99 (from torch)\n",
      "  Downloading nvidia_cuda_runtime_cu11-11.7.99-py3-none-manylinux1_x86_64.whl (849 kB)\n",
      "\u001b[2K     \u001b[38;2;114;156;31m━━━━━━━━━━━━━━━━━━━━━━━━━━━━━━━━━━━━━━━\u001b[0m \u001b[32m849.3/849.3 kB\u001b[0m \u001b[31m2.7 MB/s\u001b[0m eta \u001b[36m0:00:00\u001b[0mm eta \u001b[36m0:00:01\u001b[0m0:01\u001b[0m:01\u001b[0m\n",
      "\u001b[?25hCollecting nvidia-cuda-cupti-cu11==11.7.101 (from torch)\n",
      "  Downloading nvidia_cuda_cupti_cu11-11.7.101-py3-none-manylinux1_x86_64.whl (11.8 MB)\n",
      "\u001b[2K     \u001b[38;2;114;156;31m━━━━━━━━━━━━━━━━━━━━━━━━━━━━━━━━━━━━━━━━\u001b[0m \u001b[32m11.8/11.8 MB\u001b[0m \u001b[31m2.1 MB/s\u001b[0m eta \u001b[36m0:00:00\u001b[0mm eta \u001b[36m0:00:01\u001b[0m[36m0:00:01\u001b[0m\n",
      "\u001b[?25hCollecting nvidia-cudnn-cu11==8.5.0.96 (from torch)\n",
      "  Downloading nvidia_cudnn_cu11-8.5.0.96-2-py3-none-manylinux1_x86_64.whl (557.1 MB)\n",
      "\u001b[2K     \u001b[38;2;114;156;31m━━━━━━━━━━━━━━━━━━━━━━━━━━━━━━━━━━━━━\u001b[0m \u001b[32m557.1/557.1 MB\u001b[0m \u001b[31m835.2 kB/s\u001b[0m eta \u001b[36m0:00:00\u001b[0mm eta \u001b[36m0:00:01\u001b[0m[36m0:00:06\u001b[0m\n",
      "\u001b[?25h\u001b[33mWARNING: Retrying (Retry(total=4, connect=None, read=None, redirect=None, status=None)) after connection broken by 'ReadTimeoutError(\"HTTPSConnectionPool(host='pypi.org', port=443): Read timed out. (read timeout=15)\")': /simple/nvidia-cublas-cu11/\u001b[0m\u001b[33m\n",
      "\u001b[0mCollecting nvidia-cublas-cu11==11.10.3.66 (from torch)\n",
      "  Downloading nvidia_cublas_cu11-11.10.3.66-py3-none-manylinux1_x86_64.whl (317.1 MB)\n",
      "\u001b[2K     \u001b[38;2;114;156;31m━━━━━━━━━━━━━━━━━━━━━━━━━━━━━━━━━━━━━━━\u001b[0m \u001b[32m317.1/317.1 MB\u001b[0m \u001b[31m1.2 MB/s\u001b[0m eta \u001b[36m0:00:00\u001b[0mm eta \u001b[36m0:00:01\u001b[0m[36m0:00:05\u001b[0m\n",
      "\u001b[?25hCollecting nvidia-cufft-cu11==10.9.0.58 (from torch)\n",
      "  Downloading nvidia_cufft_cu11-10.9.0.58-py3-none-manylinux1_x86_64.whl (168.4 MB)\n",
      "\u001b[2K     \u001b[38;2;114;156;31m━━━━━━━━━━━━━━━━━━━━━━━━━━━━━━━━━━━━━━━\u001b[0m \u001b[32m168.4/168.4 MB\u001b[0m \u001b[31m2.3 MB/s\u001b[0m eta \u001b[36m0:00:00\u001b[0mm eta \u001b[36m0:00:01\u001b[0m[36m0:00:02\u001b[0m\n",
      "\u001b[?25hCollecting nvidia-curand-cu11==10.2.10.91 (from torch)\n",
      "  Downloading nvidia_curand_cu11-10.2.10.91-py3-none-manylinux1_x86_64.whl (54.6 MB)\n",
      "\u001b[2K     \u001b[38;2;114;156;31m━━━━━━━━━━━━━━━━━━━━━━━━━━━━━━━━━━━━━━━━\u001b[0m \u001b[32m54.6/54.6 MB\u001b[0m \u001b[31m3.6 MB/s\u001b[0m eta \u001b[36m0:00:00\u001b[0mm eta \u001b[36m0:00:01\u001b[0m[36m0:00:01\u001b[0m\n",
      "\u001b[?25hCollecting nvidia-cusolver-cu11==11.4.0.1 (from torch)\n",
      "  Downloading nvidia_cusolver_cu11-11.4.0.1-2-py3-none-manylinux1_x86_64.whl (102.6 MB)\n",
      "\u001b[2K     \u001b[38;2;114;156;31m━━━━━━━━━━━━━━━━━━━━━━━━━━━━━━━━━━━━━━━\u001b[0m \u001b[32m102.6/102.6 MB\u001b[0m \u001b[31m2.2 MB/s\u001b[0m eta \u001b[36m0:00:00\u001b[0mm eta \u001b[36m0:00:01\u001b[0m[36m0:00:01\u001b[0m\n",
      "\u001b[?25hCollecting nvidia-cusparse-cu11==11.7.4.91 (from torch)\n",
      "  Downloading nvidia_cusparse_cu11-11.7.4.91-py3-none-manylinux1_x86_64.whl (173.2 MB)\n",
      "\u001b[2K     \u001b[38;2;249;38;114m━━━━━━━━━━━━━━━━━━━━━━━━━━━━━━━━━━━━━\u001b[0m\u001b[38;2;249;38;114m╸\u001b[0m\u001b[38;5;237m━\u001b[0m \u001b[32m167.2/173.2 MB\u001b[0m \u001b[31m3.8 MB/s\u001b[0m eta \u001b[36m0:00:02\u001b[0m\n",
      "\u001b[?25h\u001b[31mERROR: Exception:\n",
      "Traceback (most recent call last):\n",
      "  File \"/home/mohammad/anaconda3/lib/python3.9/site-packages/pip/_vendor/urllib3/response.py\", line 438, in _error_catcher\n",
      "    yield\n",
      "  File \"/home/mohammad/anaconda3/lib/python3.9/site-packages/pip/_vendor/urllib3/response.py\", line 561, in read\n",
      "    data = self._fp_read(amt) if not fp_closed else b\"\"\n",
      "  File \"/home/mohammad/anaconda3/lib/python3.9/site-packages/pip/_vendor/urllib3/response.py\", line 527, in _fp_read\n",
      "    return self._fp.read(amt) if amt is not None else self._fp.read()\n",
      "  File \"/home/mohammad/anaconda3/lib/python3.9/site-packages/pip/_vendor/cachecontrol/filewrapper.py\", line 90, in read\n",
      "    data = self.__fp.read(amt)\n",
      "  File \"/home/mohammad/anaconda3/lib/python3.9/http/client.py\", line 463, in read\n",
      "    n = self.readinto(b)\n",
      "  File \"/home/mohammad/anaconda3/lib/python3.9/http/client.py\", line 507, in readinto\n",
      "    n = self.fp.readinto(b)\n",
      "  File \"/home/mohammad/anaconda3/lib/python3.9/socket.py\", line 704, in readinto\n",
      "    return self._sock.recv_into(b)\n",
      "  File \"/home/mohammad/anaconda3/lib/python3.9/ssl.py\", line 1242, in recv_into\n",
      "    return self.read(nbytes, buffer)\n",
      "  File \"/home/mohammad/anaconda3/lib/python3.9/ssl.py\", line 1100, in read\n",
      "    return self._sslobj.read(len, buffer)\n",
      "ConnectionResetError: [Errno 104] Connection reset by peer\n",
      "\n",
      "During handling of the above exception, another exception occurred:\n",
      "\n",
      "Traceback (most recent call last):\n",
      "  File \"/home/mohammad/anaconda3/lib/python3.9/site-packages/pip/_internal/cli/base_command.py\", line 169, in exc_logging_wrapper\n",
      "    status = run_func(*args)\n",
      "  File \"/home/mohammad/anaconda3/lib/python3.9/site-packages/pip/_internal/cli/req_command.py\", line 248, in wrapper\n",
      "    return func(self, options, args)\n",
      "  File \"/home/mohammad/anaconda3/lib/python3.9/site-packages/pip/_internal/commands/install.py\", line 377, in run\n",
      "    requirement_set = resolver.resolve(\n",
      "  File \"/home/mohammad/anaconda3/lib/python3.9/site-packages/pip/_internal/resolution/resolvelib/resolver.py\", line 92, in resolve\n",
      "    result = self._result = resolver.resolve(\n",
      "  File \"/home/mohammad/anaconda3/lib/python3.9/site-packages/pip/_vendor/resolvelib/resolvers.py\", line 546, in resolve\n",
      "    state = resolution.resolve(requirements, max_rounds=max_rounds)\n",
      "  File \"/home/mohammad/anaconda3/lib/python3.9/site-packages/pip/_vendor/resolvelib/resolvers.py\", line 427, in resolve\n",
      "    failure_causes = self._attempt_to_pin_criterion(name)\n",
      "  File \"/home/mohammad/anaconda3/lib/python3.9/site-packages/pip/_vendor/resolvelib/resolvers.py\", line 239, in _attempt_to_pin_criterion\n",
      "    criteria = self._get_updated_criteria(candidate)\n",
      "  File \"/home/mohammad/anaconda3/lib/python3.9/site-packages/pip/_vendor/resolvelib/resolvers.py\", line 230, in _get_updated_criteria\n",
      "    self._add_to_criteria(criteria, requirement, parent=candidate)\n",
      "  File \"/home/mohammad/anaconda3/lib/python3.9/site-packages/pip/_vendor/resolvelib/resolvers.py\", line 173, in _add_to_criteria\n",
      "    if not criterion.candidates:\n",
      "  File \"/home/mohammad/anaconda3/lib/python3.9/site-packages/pip/_vendor/resolvelib/structs.py\", line 156, in __bool__\n",
      "    return bool(self._sequence)\n",
      "  File \"/home/mohammad/anaconda3/lib/python3.9/site-packages/pip/_internal/resolution/resolvelib/found_candidates.py\", line 155, in __bool__\n",
      "    return any(self)\n",
      "  File \"/home/mohammad/anaconda3/lib/python3.9/site-packages/pip/_internal/resolution/resolvelib/found_candidates.py\", line 143, in <genexpr>\n",
      "    return (c for c in iterator if id(c) not in self._incompatible_ids)\n",
      "  File \"/home/mohammad/anaconda3/lib/python3.9/site-packages/pip/_internal/resolution/resolvelib/found_candidates.py\", line 47, in _iter_built\n",
      "    candidate = func()\n",
      "  File \"/home/mohammad/anaconda3/lib/python3.9/site-packages/pip/_internal/resolution/resolvelib/factory.py\", line 206, in _make_candidate_from_link\n",
      "    self._link_candidate_cache[link] = LinkCandidate(\n",
      "  File \"/home/mohammad/anaconda3/lib/python3.9/site-packages/pip/_internal/resolution/resolvelib/candidates.py\", line 293, in __init__\n",
      "    super().__init__(\n",
      "  File \"/home/mohammad/anaconda3/lib/python3.9/site-packages/pip/_internal/resolution/resolvelib/candidates.py\", line 156, in __init__\n",
      "    self.dist = self._prepare()\n",
      "  File \"/home/mohammad/anaconda3/lib/python3.9/site-packages/pip/_internal/resolution/resolvelib/candidates.py\", line 225, in _prepare\n",
      "    dist = self._prepare_distribution()\n",
      "  File \"/home/mohammad/anaconda3/lib/python3.9/site-packages/pip/_internal/resolution/resolvelib/candidates.py\", line 304, in _prepare_distribution\n",
      "    return preparer.prepare_linked_requirement(self._ireq, parallel_builds=True)\n",
      "  File \"/home/mohammad/anaconda3/lib/python3.9/site-packages/pip/_internal/operations/prepare.py\", line 516, in prepare_linked_requirement\n",
      "    return self._prepare_linked_requirement(req, parallel_builds)\n",
      "  File \"/home/mohammad/anaconda3/lib/python3.9/site-packages/pip/_internal/operations/prepare.py\", line 587, in _prepare_linked_requirement\n",
      "    local_file = unpack_url(\n",
      "  File \"/home/mohammad/anaconda3/lib/python3.9/site-packages/pip/_internal/operations/prepare.py\", line 166, in unpack_url\n",
      "    file = get_http_url(\n",
      "  File \"/home/mohammad/anaconda3/lib/python3.9/site-packages/pip/_internal/operations/prepare.py\", line 107, in get_http_url\n",
      "    from_path, content_type = download(link, temp_dir.path)\n",
      "  File \"/home/mohammad/anaconda3/lib/python3.9/site-packages/pip/_internal/network/download.py\", line 147, in __call__\n",
      "    for chunk in chunks:\n",
      "  File \"/home/mohammad/anaconda3/lib/python3.9/site-packages/pip/_internal/cli/progress_bars.py\", line 53, in _rich_progress_bar\n",
      "    for chunk in iterable:\n",
      "  File \"/home/mohammad/anaconda3/lib/python3.9/site-packages/pip/_internal/network/utils.py\", line 63, in response_chunks\n",
      "    for chunk in response.raw.stream(\n",
      "  File \"/home/mohammad/anaconda3/lib/python3.9/site-packages/pip/_vendor/urllib3/response.py\", line 622, in stream\n",
      "    data = self.read(amt=amt, decode_content=decode_content)\n",
      "  File \"/home/mohammad/anaconda3/lib/python3.9/site-packages/pip/_vendor/urllib3/response.py\", line 587, in read\n",
      "    raise IncompleteRead(self._fp_bytes_read, self.length_remaining)\n",
      "  File \"/home/mohammad/anaconda3/lib/python3.9/contextlib.py\", line 137, in __exit__\n",
      "    self.gen.throw(typ, value, traceback)\n",
      "  File \"/home/mohammad/anaconda3/lib/python3.9/site-packages/pip/_vendor/urllib3/response.py\", line 455, in _error_catcher\n",
      "    raise ProtocolError(\"Connection broken: %r\" % e, e)\n",
      "pip._vendor.urllib3.exceptions.ProtocolError: (\"Connection broken: ConnectionResetError(104, 'Connection reset by peer')\", ConnectionResetError(104, 'Connection reset by peer'))\u001b[0m\u001b[31m\n"
     ]
    },
    {
     "name": "stdout",
     "output_type": "stream",
     "text": [
      "\u001b[0m\u001b[33mWARNING: Retrying (Retry(total=4, connect=None, read=None, redirect=None, status=None)) after connection broken by 'NewConnectionError('<pip._vendor.urllib3.connection.HTTPSConnection object at 0x7f14be43a730>: Failed to establish a new connection: [Errno 101] Network is unreachable')': /simple/torchvision/\u001b[0m\u001b[33m\n",
      "\u001b[0m\u001b[33mWARNING: Retrying (Retry(total=3, connect=None, read=None, redirect=None, status=None)) after connection broken by 'NewConnectionError('<pip._vendor.urllib3.connection.HTTPSConnection object at 0x7f14be43aa60>: Failed to establish a new connection: [Errno 101] Network is unreachable')': /simple/torchvision/\u001b[0m\u001b[33m\n",
      "\u001b[0m\u001b[33mWARNING: Retrying (Retry(total=2, connect=None, read=None, redirect=None, status=None)) after connection broken by 'NewConnectionError('<pip._vendor.urllib3.connection.HTTPSConnection object at 0x7f14be43acd0>: Failed to establish a new connection: [Errno 101] Network is unreachable')': /simple/torchvision/\u001b[0m\u001b[33m\n",
      "\u001b[0m\u001b[33mWARNING: Retrying (Retry(total=1, connect=None, read=None, redirect=None, status=None)) after connection broken by 'NewConnectionError('<pip._vendor.urllib3.connection.HTTPSConnection object at 0x7f14be43aeb0>: Failed to establish a new connection: [Errno 101] Network is unreachable')': /simple/torchvision/\u001b[0m\u001b[33m\n",
      "\u001b[0m\u001b[33mWARNING: Retrying (Retry(total=0, connect=None, read=None, redirect=None, status=None)) after connection broken by 'NewConnectionError('<pip._vendor.urllib3.connection.HTTPSConnection object at 0x7f14be43af70>: Failed to establish a new connection: [Errno 101] Network is unreachable')': /simple/torchvision/\u001b[0m\u001b[33m\n",
      "\u001b[0m\u001b[31mERROR: Could not find a version that satisfies the requirement torchvision (from versions: none)\u001b[0m\u001b[31m\n",
      "\u001b[0m\u001b[31mERROR: No matching distribution found for torchvision\u001b[0m\u001b[31m\n",
      "\u001b[0m"
     ]
    }
   ],
   "source": [
    "# installing library for project\n",
    "!pip install tensorflow\n",
    "!pip install keras\n",
    "!pip install torch\n",
    "!pip install torchvision"
   ]
  },
  {
   "cell_type": "code",
   "execution_count": null,
   "id": "ef2f2784",
   "metadata": {},
   "outputs": [],
   "source": []
  }
 ],
 "metadata": {
  "kernelspec": {
   "display_name": "Python 3 (ipykernel)",
   "language": "python",
   "name": "python3"
  },
  "language_info": {
   "codemirror_mode": {
    "name": "ipython",
    "version": 3
   },
   "file_extension": ".py",
   "mimetype": "text/x-python",
   "name": "python",
   "nbconvert_exporter": "python",
   "pygments_lexer": "ipython3",
   "version": "3.9.13"
  }
 },
 "nbformat": 4,
 "nbformat_minor": 5
}
